Workbook

Sheet Control Panel
A1: Yearly Staff Attendance Control Panel
A2: Control | B2: Value | H2: Status Key | I2: Meaning
A3: Attendance year | B3: 2026 | H3: P | I3: Present
A4: Instructions | B4: 1) Enter employee details in Employee Master. 2) Enter annual holiday dates in column H if you want a holiday calendar reference only. 3) Record daily status codes in Jan-Dec. 4) All calendar days are treated as work days unless an absence status is entered. 5) KPI Live Tracker and Staff Absence Audit update automatically. | H4: AA | I4: Authorised Absence
H5: UA | I5: Unauthorised Absence
A6: Active Employees | B6: =COUNTIFS('Employee Master'!A8:A107,"?*",'Employee Master'!D8:D107,"Active") | H6: SA | I6: Sickness Absence
A7: Annual Calendar Work Days | B7: =SUM('KPI Live Tracker'!B19:B30) | H7: EA | I7: Emergency Absence
H8: OR | I8: Other Reason
H9: WO | I9: Weekend Off / Approved Rest Day
H10: H | I10: Holiday / Approved Leave
H12: Holiday Date | I12: Holiday Name / Note

Sheet Employee Master
A1: Employee Master Register
A3: Enter employee details once here. Jan-Dec sheets synchronise automatically.
A6: Employee ID | B6: Employee Name | C6: Reported To | D6: Status | E6: Notes
A8: Abiodun Oguntula | B8: Abiodun Oguntula | C8: HR Manager | D8: Active
A9: Adesoji Aderemi Adeboye | B9: Adesoji Aderemi Adeboye | C9: HR Manager | D9: Active
A10: Ajoke Idowu Olatunde | B10: Ajoke Idowu Olatunde | C10: HR Manager | D10: Active
A11: Akash Amin | B11: Akash Amin | C11: HR Manager | D11: Active
A12: Amrit Singh | B12: Amrit Singh | C12: HR Manager | D12: Active
A13: Anthonia Ekenedilichukwu | B13: Anthonia Ekenedilichukwu | C13: HR Manager | D13: Active
A14: Bankole Funmilayo | B14: Bankole Funmilayo | C14: HR Manager | D14: Active
A15: Bekezela Mguni | B15: Bekezela Mguni | C15: HR Manager | D15: Active
A16: Bukola Gbadamosi | B16: Bukola Gbadamosi | C16: HR Manager | D16: Active
A17: Chinua Ibe-Ani | B17: Chinua Ibe-Ani | C17: HR Manager | D17: Active
A18: Deborah Awotedu | B18: Deborah Awotedu | C18: HR Manager | D18: Active
A19: Deborah Awuyuse | B19: Deborah Awuyuse | C19: HR Manager | D19: Active
... A71: Zaheer Abbas | B71: Zaheer Abbas | C71: HR Manager | D71: Active
D72: Active
D73: Active
D74: Active
D75: Active
D76: Active
D77: Active
D78: Active
D79: Active
D80: Active
D81: Active
D82: Active
D83: Active
... D107: Active

Sheet Jan
A1: January Monthly Staff Attendance Master Register
A2: Month Start | B2: =DATE('Control Panel'!$B$3,1,1) | D2: Reporting Month | E2: =TEXT($B$2,"mmmm yyyy") | H2: Working Days | I2: =COUNTA($D$4:$AH$4) | K2: Active Employees | L2: =COUNTIFS('Employee Master'!A8:A107,"?*",'Employee Master'!D8:D107,"Active") | AW2: Status | AX2: Meaning
A3: Enter daily statuses using: P, AA, UA, SA, EA, OR, WO, H. All calendar days from the 1st to the last day of the month are treated as work days, including weekends and public holidays, unless an absence status is entered. | AV3: P | AW3: P | AX3: Present
D4: =IF(COLUMN()-3<=DAY(DATE(YEAR($B$2),MONTH($B$2)+1,0)),DATE(YEAR($B$2),MONTH($B$2),COLUMN()-3),"") | E4: =IF(COLUMN()-3<=DAY(DATE(YEAR($B$2),MONTH($B$2)+1,0)),DATE(YEAR($B$2),MONTH($B$2),COLUMN()-3),"") | F4: =IF(COLUMN()-3<=DAY(DATE(YEAR($B$2),MONTH($B$2)+1,0)),DATE(YEAR($B$2),MONTH($B$2),COLUMN()-3),"") | G4: =IF(COLUMN()-3<=DAY(DATE(YEAR($B$2),MONTH($B$2)+1,0)),DATE(YEAR($B$2),MONTH($B$2),COLUMN()-3),"") | H4: =IF(COLUMN()-3<=DAY(DATE(YEAR($B$2),MONTH($B$2)+1,0)),DATE(YEAR($B$2),MONTH($B$2),COLUMN()-3),"") | I4: =IF(COLUMN()-3<=DAY(DATE(YEAR($B$2),MONTH($B$2)+1,0)),DATE(YEAR($B$2),MONTH($B$2),COLUMN()-3),"") | J4: =IF(COLUMN()-3<=DAY(DATE(YEAR($B$2),MONTH($B$2)+1,0)),DATE(YEAR($B$2),MONTH($B$2),COLUMN()-3),"") | K4: =IF(COLUMN()-3<=DAY(DATE(YEAR($B$2),MONTH($B$2)+1,0)),DATE(YEAR($B$2),MONTH($B$2),COLUMN()-3),"") | ... AH4: =IF(COLUMN()-3<=DAY(DATE(YEAR($B$2),MONTH($B$2)+1,0)),DATE(YEAR($B$2),MONTH($B$2),COLUMN()-3),"") | AV4: AA | AW4: Authorised Attendance | AX4: Authorised Attendance
A5: Employee Details | D5: Daily Attendance Status | AI5: Monthly Summary & Forensic Review | AV5: UA | AW5: Unauthorised Attendance | AX5: Unauthorised Attendance
A6: Employee ID | B6: Employee Name | C6: Reported To | D6: =IF(D$4="","",DAY(D$4)) | E6: =IF(E$4="","",DAY(E$4)) | F6: =IF(F$4="","",DAY(F$4)) | G6: =IF(G$4="","",DAY(G$4)) | H6: =IF(H$4="","",DAY(H$4)) | I6: =IF(I$4="","",DAY(I$4)) | J6: =IF(J$4="","",DAY(J$4)) | K6: =IF(K$4="","",DAY(K$4)) | ... AH6: =IF(AH$4="","",DAY(AH$4)) | AI6: Present | AJ6: Authorised Absence | AK6: Unauthorised Absence | AL6: Sickness Absence | AM6: Emergency Absence | AN6: Other Reason | AO6: Weekend Off | AP6: Holiday | AQ6: Absence Reason | AR6: Remarks | AS6: Attendance % | AT6: Compliance % | AU6: Forensic Flag | AV6: SA | AW6: Sick Absence | AX6: Sick Absence
D7: =IF(D$4="","","WD") | E7: =IF(E$4="","","WD") | F7: =IF(F$4="","","WD") | G7: =IF(G$4="","","WD") | H7: =IF(H$4="","","WD") | I7: =IF(I$4="","","WD") | J7: =IF(J$4="","","WD") | K7: =IF(K$4="","","WD") | ... AH7: =IF(AH$4="","","WD") | AV7: EA | AW7: Emergency Absence | AX7: Emergency Absence
A8: =IF('Employee Master'!A8="","",'Employee Master'!A8) | B8: =IF($A8="","",'Employee Master'!B8) | C8: =IF($A8="","",'Employee Master'!C8) | D8: P | E8: P | F8: P | G8: P | H8: P | I8: P | J8: P | K8: P | L8: P | M8: P | N8: P | O8: P | P8: P | Q8: P | R8: P | S8: P | T8: P | U8: P | V8: P | W8: P | X8: P | Y8: P | Z8: P | AA8: P | AB8: P | AC8: P | AD8: P | AE8: P | AF8: P | AG8: P | AH8: P | AI8: =IF($A8="","",COUNTIF($D8:$AH8,"P")) | AJ8: =IF($A8="","",COUNTIF($D8:$AH8,"AA")+COUNTIF($D8:$AH8,"SA")+COUNTIF($D8:$AH8,"EA")+COUNTIF($D8:$AH8,"OR")+COUNTIF($D8:$AH8,"WO")+COUNTIF($D8:$AH8,"H")) | AK8: =IF($A8="","",COUNTIF($D8:$AH8,"UA")) | AL8: =IF($A8="","",COUNTIF($D8:$AH8,"SA")) | AM8: =IF($A8="","",COUNTIF($D8:$AH8,"EA")) | AN8: =IF($A8="","",COUNTIF($D8:$AH8,"OR")) | AO8: =IF($A8="","",COUNTIF($D8:$AH8,"WO")) | AP8: =IF($A8="","",COUNTIF($D8:$AH8,"H")) | AS8: =IF(OR($A8="",$I$2=0),"",AI8/$I$2) | AT8: =IF(OR($A8="",$I$2=0),"",(AI8+AJ8)/$I$2) | AU8: =IF($A8="","",IF(OR($AK8>=2,AND($AK8>0,$AQ8=""),AND($AK8>0,$AR8="")),"CRITICAL",IF(OR($AK8=1,AND(($AJ8)>0,$AQ8=""),AND(($AJ8)>0,$AR8=""),$AT8<0.95),"REVIEW","OK"))) | AV8: OR | AW8: Other Reason | AX8: Other Reason
A9: =IF('Employee Master'!A9="","",'Employee Master'!A9) | B9: =IF($A9="","",'Employee Master'!B9) | C9: =IF($A9="","",'Employee Master'!C9) | D9: P | E9: P | F9: P | G9: P | H9: UA | I9: UA | J9: UA | K9: UA | L9: UA | M9: UA | N9: UA | O9: UA | P9: UA | Q9: UA | R9: UA | S9: UA | T9: UA | U9: UA | V9: UA | W9: UA | X9: UA | Y9: UA | Z9: UA | AA9: UA | AB9: UA | AC9: UA | AD9: UA | AE9: UA | AF9: UA | AG9: UA | AH9: UA | AI9: =IF($A9="","",COUNTIF($D9:$AH9,"P")) | AJ9: =IF($A9="","",COUNTIF($D9:$AH9,"AA")+COUNTIF($D9:$AH9,"SA")+COUNTIF($D9:$AH9,"EA")+COUNTIF($D9:$AH9,"OR")+COUNTIF($D9:$AH9,"WO")+COUNTIF($D9:$AH9,"H")) | AK9: =IF($A9="","",COUNTIF($D9:$AH9,"UA")) | AL9: =IF($A9="","",COUNTIF($D9:$AH9,"SA")) | AM9: =IF($A9="","",COUNTIF($D9:$AH9,"EA")) | AN9: =IF($A9="","",COUNTIF($D9:$AH9,"OR")) | AO9: =IF($A9="","",COUNTIF($D9:$AH9,"WO")) | AP9: =IF($A9="","",COUNTIF($D9:$AH9,"H")) | AS9: =IF(OR($A9="",$I$2=0),"",AI9/$I$2) | AT9: =IF(OR($A9="",$I$2=0),"",(AI9+AJ9)/$I$2) | AU9: =IF($A9="","",IF(OR($AK9>=2,AND($AK9>0,$AQ9=""),AND($AK9>0,$AR9="")),"CRITICAL",IF(OR($AK9=1,AND(($AJ9)>0,$AQ9=""),AND(($AJ9)>0,$AR9=""),$AT9<0.95),"REVIEW","OK"))) | AV9: WO | AW9: Weekend Off / Approved Rest Day | AX9: Weekend Off
A10: =IF('Employee Master'!A10="","",'Employee Master'!A10) | B10: =IF($A10="","",'Employee Master'!B10) | C10: =IF($A10="","",'Employee Master'!C10) | D10: UA | E10: UA | F10: UA | G10: UA | H10: P | I10: P | J10: P | K10: UA | L10: P | M10: P | N10: P | O10: P | P10: P | Q10: P | R10: P | S10: P | T10: P | U10: P | V10: P | W10: P | X10: P | Y10: P | Z10: P | AA10: P | AB10: P | AC10: P | AD10: P | AE10: P | AF10: P | AG10: P | AH10: P | AI10: =IF($A10="","",COUNTIF($D10:$AH10,"P")) | AJ10: =IF($A10="","",COUNTIF($D10:$AH10,"AA")+COUNTIF($D10:$AH10,"SA")+COUNTIF($D10:$AH10,"EA")+COUNTIF($D10:$AH10,"OR")+COUNTIF($D10:$AH10,"WO")+COUNTIF($D10:$AH10,"H")) | AK10: =IF($A10="","",COUNTIF($D10:$AH10,"UA")) | AL10: =IF($A10="","",COUNTIF($D10:$AH10,"SA")) | AM10: =IF($A10="","",COUNTIF($D10:$AH10,"EA")) | AN10: =IF($A10="","",COUNTIF($D10:$AH10,"OR")) | AO10: =IF($A10="","",COUNTIF($D10:$AH10,"WO")) | AP10: =IF($A10="","",COUNTIF($D10:$AH10,"H")) | AS10: =IF(OR($A10="",$I$2=0),"",AI10/$I$2) | AT10: =IF(OR($A10="",$I$2=0),"",(AI10+AJ10)/$I$2) | AU10: =IF($A10="","",IF(OR($AK10>=2,AND($AK10>0,$AQ10=""),AND($AK10>0,$AR10="")),"CRITICAL",IF(OR($AK10=1,AND(($AJ10)>0,$AQ10=""),AND(($AJ10)>0,$AR10=""),$AT10<0.95),"REVIEW","OK"))) | AV10: H | AW10: Holiday / Approved Leave | AX10: Holiday
A11: =IF('Employee Master'!A11="","",'Employee Master'!A11) | B11: =IF($A11="","",'Employee Master'!B11) | C11: =IF($A11="","",'Employee Master'!C11) | D11: P | E11: UA | F11: UA | G11: UA | H11: UA | I11: UA | J11: UA | K11: UA | L11: UA | M11: UA | N11: UA | O11: UA | P11: UA | Q11: UA | R11: UA | S11: UA | T11: UA | U11: UA | V11: UA | W11: UA | X11: UA | Y11: UA | Z11: UA | AA11: UA | AB11: UA | AC11: UA | AD11: UA | AE11: UA | AF11: UA | AG11: UA | AH11: UA | AI11: =IF($A11="","",COUNTIF($D11:$AH11,"P")) | AJ11: =IF($A11="","",COUNTIF($D11:$AH11,"AA")+COUNTIF($D11:$AH11,"SA")+COUNTIF($D11:$AH11,"EA")+COUNTIF($D11:$AH11,"OR")+COUNTIF($D11:$AH11,"WO")+COUNTIF($D11:$AH11,"H")) | AK11: =IF($A11="","",COUNTIF($D11:$AH11,"UA")) | AL11: =IF($A11="","",COUNTIF($D11:$AH11,"SA")) | AM11: =IF($A11="","",COUNTIF($D11:$AH11,"EA")) | AN11: =IF($A11="","",COUNTIF($D11:$AH11,"OR")) | AO11: =IF($A11="","",COUNTIF($D11:$AH11,"WO")) | AP11: =IF($A11="","",COUNTIF($D11:$AH11,"H")) | AS11: =IF(OR($A11="",$I$2=0),"",AI11/$I$2) | AT11: =IF(OR($A11="",$I$2=0),"",(AI11+AJ11)/$I$2) | AU11: =IF($A11="","",IF(OR($AK11>=2,AND($AK11>0,$AQ11=""),AND($AK11>0,$AR11="")),"CRITICAL",IF(OR($AK11=1,AND(($AJ11)>0,$AQ11=""),AND(($AJ11)>0,$AR11=""),$AT11<0.95),"REVIEW","OK")))
A12: =IF('Employee Master'!A12="","",'Employee Master'!A12) | B12: =IF($A12="","",'Employee Master'!B12) | C12: =IF($A12="","",'Employee Master'!C12) | D12: P | E12: P | F12: P | G12: P | H12: P | I12: P | J12: P | K12: P | L12: P | M12: P | N12: P | O12: P | P12: P | Q12: P | R12: P | S12: P | T12: P | U12: P | V12: P | W12: P | X12: P | Y12: P | Z12: P | AA12: P | AB12: P | AC12: P | AD12: P | AE12: P | AF12: P | AG12: P | AH12: P | AI12: =IF($A12="","",COUNTIF($D12:$AH12,"P")) | AJ12: =IF($A12="","",COUNTIF($D12:$AH12,"AA")+COUNTIF($D12:$AH12,"SA")+COUNTIF($D12:$AH12,"EA")+COUNTIF($D12:$AH12,"OR")+COUNTIF($D12:$AH12,"WO")+COUNTIF($D12:$AH12,"H")) | AK12: =IF($A12="","",COUNTIF($D12:$AH12,"UA")) | AL12: =IF($A12="","",COUNTIF($D12:$AH12,"SA")) | AM12: =IF($A12="","",COUNTIF($D12:$AH12,"EA")) | AN12: =IF($A12="","",COUNTIF($D12:$AH12,"OR")) | AO12: =IF($A12="","",COUNTIF($D12:$AH12,"WO")) | AP12: =IF($A12="","",COUNTIF($D12:$AH12,"H")) | AS12: =IF(OR($A12="",$I$2=0),"",AI12/$I$2) | AT12: =IF(OR($A12="",$I$2=0),"",(AI12+AJ12)/$I$2) | AU12: =IF($A12="","",IF(OR($AK12>=2,AND($AK12>0,$AQ12=""),AND($AK12>0,$AR12="")),"CRITICAL",IF(OR($AK12=1,AND(($AJ12)>0,$AQ12=""),AND(($AJ12)>0,$AR12=""),$AT12<0.95),"REVIEW","OK")))
A13: =IF('Employee Master'!A13="","",'Employee Master'!A13) | B13: =IF($A13="","",'Employee Master'!B13) | C13: =IF($A13="","",'Employee Master'!C13) | D13: P | E13: P | F13: P | G13: P | H13: P | I13: P | J13: P | K13: P | L13: P | M13: P | N13: P | O13: P | P13: P | Q13: P | R13: P | S13: P | T13: P | U13: P | V13: P | W13: P | X13: P | Y13: P | Z13: P | AA13: P | AB13: P | AC13: P | AD13: P | AE13: P | AF13: P | AG13: P | AH13: P | AI13: =IF($A13="","",COUNTIF($D13:$AH13,"P")) | AJ13: =IF($A13="","",COUNTIF($D13:$AH13,"AA")+COUNTIF($D13:$AH13,"SA")+COUNTIF($D13:$AH13,"EA")+COUNTIF($D13:$AH13,"OR")+COUNTIF($D13:$AH13,"WO")+COUNTIF($D13:$AH13,"H")) | AK13: =IF($A13="","",COUNTIF($D13:$AH13,"UA")) | AL13: =IF($A13="","",COUNTIF($D13:$AH13,"SA")) | AM13: =IF($A13="","",COUNTIF($D13:$AH13,"EA")) | AN13: =IF($A13="","",COUNTIF($D13:$AH13,"OR")) | AO13: =IF($A13="","",COUNTIF($D13:$AH13,"WO")) | AP13: =IF($A13="","",COUNTIF($D13:$AH13,"H")) | AS13: =IF(OR($A13="",$I$2=0),"",AI13/$I$2) | AT13: =IF(OR($A13="",$I$2=0),"",(AI13+AJ13)/$I$2) | AU13: =IF($A13="","",IF(OR($AK13>=2,AND($AK13>0,$AQ13=""),AND($AK13>0,$AR13="")),"CRITICAL",IF(OR($AK13=1,AND(($AJ13)>0,$AQ13=""),AND(($AJ13)>0,$AR13=""),$AT13<0.95),"REVIEW","OK")))
A14: =IF('Employee Master'!A14="","",'Employee Master'!A14) | B14: =IF($A14="","",'Employee Master'!B14) | C14: =IF($A14="","",'Employee Master'!C14) | D14: P | E14: P | F14: P | G14: P | H14: P | I14: P | J14: P | K14: P | L14: P | M14: P | N14: P | O14: P | P14: P | Q14: P | R14: P | S14: P | T14: P | U14: P | V14: P | W14: P | X14: P | Y14: P | Z14: P | AA14: P | AB14: P | AC14: P | AD14: P | AE14: P | AF14: P | AG14: P | AH14: P | AI14: =IF($A14="","",COUNTIF($D14:$AH14,"P")) | AJ14: =IF($A14="","",COUNTIF($D14:$AH14,"AA")+COUNTIF($D14:$AH14,"SA")+COUNTIF($D14:$AH14,"EA")+COUNTIF($D14:$AH14,"OR")+COUNTIF($D14:$AH14,"WO")+COUNTIF($D14:$AH14,"H")) | AK14: =IF($A14="","",COUNTIF($D14:$AH14,"UA")) | AL14: =IF($A14="","",COUNTIF($D14:$AH14,"SA")) | AM14: =IF($A14="","",COUNTIF($D14:$AH14,"EA")) | AN14: =IF($A14="","",COUNTIF($D14:$AH14,"OR")) | AO14: =IF($A14="","",COUNTIF($D14:$AH14,"WO")) | AP14: =IF($A14="","",COUNTIF($D14:$AH14,"H")) | AS14: =IF(OR($A14="",$I$2=0),"",AI14/$I$2) | AT14: =IF(OR($A14="",$I$2=0),"",(AI14+AJ14)/$I$2) | AU14: =IF($A14="","",IF(OR($AK14>=2,AND($AK14>0,$AQ14=""),AND($AK14>0,$AR14="")),"CRITICAL",IF(OR($AK14=1,AND(($AJ14)>0,$AQ14=""),AND(($AJ14)>0,$AR14=""),$AT14<0.95),"REVIEW","OK")))
A15: =IF('Employee Master'!A15="","",'Employee Master'!A15) | B15: =IF($A15="","",'Employee Master'!B15) | C15: =IF($A15="","",'Employee Master'!C15) | D15: P | E15: P | F15: P | G15: P | H15: P | I15: P | J15: P | K15: P | L15: P | M15: P | N15: P | O15: P | P15: P | Q15: P | R15: P | S15: P | T15: P | U15: P | V15: UA | W15: UA | X15: P | Y15: P | Z15: P | AA15: P | AB15: P | AC15: P | AD15: P | AE15: P | AF15: P | AG15: P | AH15: P | AI15: =IF($A15="","",COUNTIF($D15:$AH15,"P")) | AJ15: =IF($A15="","",COUNTIF($D15:$AH15,"AA")+COUNTIF($D15:$AH15,"SA")+COUNTIF($D15:$AH15,"EA")+COUNTIF($D15:$AH15,"OR")+COUNTIF($D15:$AH15,"WO")+COUNTIF($D15:$AH15,"H")) | AK15: =IF($A15="","",COUNTIF($D15:$AH15,"UA")) | AL15: =IF($A15="","",COUNTIF($D15:$AH15,"SA")) | AM15: =IF($A15="","",COUNTIF($D15:$AH15,"EA")) | AN15: =IF($A15="","",COUNTIF($D15:$AH15,"OR")) | AO15: =IF($A15="","",COUNTIF($D15:$AH15,"WO")) | AP15: =IF($A15="","",COUNTIF($D15:$AH15,"H")) | AS15: =IF(OR($A15="",$I$2=0),"",AI15/$I$2) | AT15: =IF(OR($A15="",$I$2=0),"",(AI15+AJ15)/$I$2) | AU15: =IF($A15="","",IF(OR($AK15>=2,AND($AK15>0,$AQ15=""),AND($AK15>0,$AR15="")),"CRITICAL",IF(OR($AK15=1,AND(($AJ15)>0,$AQ15=""),AND(($AJ15)>0,$AR15=""),$AT15<0.95),"REVIEW","OK")))
A16: =IF('Employee Master'!A16="","",'Employee Master'!A16) | B16: =IF($A16="","",'Employee Master'!B16) | C16: =IF($A16="","",'Employee Master'!C16) | D16: P | E16: P | F16: P | G16: P | H16: P | I16: P | J16: P | K16: P | L16: P | M16: P | N16: P | O16: P | P16: P | Q16: P | R16: P | S16: P | T16: P | U16: P | V16: P | W16: P | X16: P | Y16: P | Z16: P | AA16: P | AB16: P | AC16: P | AD16: P | AE16: P | AF16: P | AG16: P | AH16: P | AI16: =IF($A16="","",COUNTIF($D16:$AH16,"P")) | AJ16: =IF($A16="","",COUNTIF($D16:$AH16,"AA")+COUNTIF($D16:$AH16,"SA")+COUNTIF($D16:$AH16,"EA")+COUNTIF($D16:$AH16,"OR")+COUNTIF($D16:$AH16,"WO")+COUNTIF($D16:$AH16,"H")) | AK16: =IF($A16="","",COUNTIF($D16:$AH16,"UA")) | AL16: =IF($A16="","",COUNTIF($D16:$AH16,"SA")) | AM16: =IF($A16="","",COUNTIF($D16:$AH16,"EA")) | AN16: =IF($A16="","",COUNTIF($D16:$AH16,"OR")) | AO16: =IF($A16="","",COUNTIF($D16:$AH16,"WO")) | AP16: =IF($A16="","",COUNTIF($D16:$AH16,"H")) | AS16: =IF(OR($A16="",$I$2=0),"",AI16/$I$2) | AT16: =IF(OR($A16="",$I$2=0),"",(AI16+AJ16)/$I$2) | AU16: =IF($A16="","",IF(OR($AK16>=2,AND($AK16>0,$AQ16=""),AND($AK16>0,$AR16="")),"CRITICAL",IF(OR($AK16=1,AND(($AJ16)>0,$AQ16=""),AND(($AJ16)>0,$AR16=""),$AT16<0.95),"REVIEW","OK")))
A17: =IF('Employee Master'!A17="","",'Employee Master'!A17) | B17: =IF($A17="","",'Employee Master'!B17) | C17: =IF($A17="","",'Employee Master'!C17) | D17: P | E17: P | F17: P | G17: P | H17: P | I17: P | J17: P | K17: P | L17: P | M17: P | N17: P | O17: P | P17: P | Q17: P | R17: P | S17: P | T17: P | U17: P | V17: P | W17: P | X17: P | Y17: P | Z17: P | AA17: P | AB17: P | AC17: P | AD17: P | AE17: P | AF17: P | AG17: P | AH17: P | AI17: =IF($A17="","",COUNTIF($D17:$AH17,"P")) | AJ17: =IF($A17="","",COUNTIF($D17:$AH17,"AA")+COUNTIF($D17:$AH17,"SA")+COUNTIF($D17:$AH17,"EA")+COUNTIF($D17:$AH17,"OR")+COUNTIF($D17:$AH17,"WO")+COUNTIF($D17:$AH17,"H")) | AK17: =IF($A17="","",COUNTIF($D17:$AH17,"UA")) | AL17: =IF($A17="","",COUNTIF($D17:$AH17,"SA")) | AM17: =IF($A17="","",COUNTIF($D17:$AH17,"EA")) | AN17: =IF($A17="","",COUNTIF($D17:$AH17,"OR")) | AO17: =IF($A17="","",COUNTIF($D17:$AH17,"WO")) | AP17: =IF($A17="","",COUNTIF($D17:$AH17,"H")) | AS17: =IF(OR($A17="",$I$2=0),"",AI17/$I$2) | AT17: =IF(OR($A17="",$I$2=0),"",(AI17+AJ17)/$I$2) | AU17: =IF($A17="","",IF(OR($AK17>=2,AND($AK17>0,$AQ17=""),AND($AK17>0,$AR17="")),"CRITICAL",IF(OR($AK17=1,AND(($AJ17)>0,$AQ17=""),AND(($AJ17)>0,$AR17=""),$AT17<0.95),"REVIEW","OK")))
A18: =IF('Employee Master'!A18="","",'Employee Master'!A18) | B18: =IF($A18="","",'Employee Master'!B18) | C18: =IF($A18="","",'Employee Master'!C18) | D18: P | E18: P | F18: P | G18: P | H18: UA | I18: UA | J18: UA | K18: UA | L18: UA | M18: UA | N18: UA | O18: UA | P18: UA | Q18: UA | R18: UA | S18: UA | T18: UA | U18: UA | V18: UA | W18: UA | X18: UA | Y18: UA | Z18: UA | AA18: UA | AB18: UA | AC18: UA | AD18: UA | AE18: UA | AF18: UA | AG18: UA | AH18: P | AI18: =IF($A18="","",COUNTIF($D18:$AH18,"P")) | AJ18: =IF($A18="","",COUNTIF($D18:$AH18,"AA")+COUNTIF($D18:$AH18,"SA")+COUNTIF($D18:$AH18,"EA")+COUNTIF($D18:$AH18,"OR")+COUNTIF($D18:$AH18,"WO")+COUNTIF($D18:$AH18,"H")) | AK18: =IF($A18="","",COUNTIF($D18:$AH18,"UA")) | AL18: =IF($A18="","",COUNTIF($D18:$AH18,"SA")) | AM18: =IF($A18="","",COUNTIF($D18:$AH18,"EA")) | AN18: =IF($A18="","",COUNTIF($D18:$AH18,"OR")) | AO18: =IF($A18="","",COUNTIF($D18:$AH18,"WO")) | AP18: =IF($A18="","",COUNTIF($D18:$AH18,"H")) | AS18: =IF(OR($A18="",$I$2=0),"",AI18/$I$2) | AT18: =IF(OR($A18="",$I$2=0),"",(AI18+AJ18)/$I$2) | AU18: =IF($A18="","",IF(OR($AK18>=2,AND($AK18>0,$AQ18=""),AND($AK18>0,$AR18="")),"CRITICAL",IF(OR($AK18=1,AND(($AJ18)>0,$AQ18=""),AND(($AJ18)>0,$AR18=""),$AT18<0.95),"REVIEW","OK")))
A19: =IF('Employee Master'!A19="","",'Employee Master'!A19) | B19: =IF($A19="","",'Employee Master'!B19) | C19: =IF($A19="","",'Employee Master'!C19) | D19: P | E19: P | F19: P | G19: P | H19: P | I19: P | J19: P | K19: P | L19: P | M19: P | N19: P | O19: P | P19: P | Q19: P | R19: P | S19: P | T19: P | U19: P | V19: P | W19: P | X19: P | Y19: P | Z19: P | AA19: P | AB19: P | AC19: UA | AD19: P | AE19: P | AF19: P | AG19: P | AH19: P | AI19: =IF($A19="","",COUNTIF($D19:$AH19,"P")) | AJ19: =IF($A19="","",COUNTIF($D19:$AH19,"AA")+COUNTIF($D19:$AH19,"SA")+COUNTIF($D19:$AH19,"EA")+COUNTIF($D19:$AH19,"OR")+COUNTIF($D19:$AH19,"WO")+COUNTIF($D19:$AH19,"H")) | AK19: =IF($A19="","",COUNTIF($D19:$AH19,"UA")) | AL19: =IF($A19="","",COUNTIF($D19:$AH19,"SA")) | AM19: =IF($A19="","",COUNTIF($D19:$AH19,"EA")) | AN19: =IF($A19="","",COUNTIF($D19:$AH19,"OR")) | AO19: =IF($A19="","",COUNTIF($D19:$AH19,"WO")) | AP19: =IF($A19="","",COUNTIF($D19:$AH19,"H")) | AS19: =IF(OR($A19="",$I$2=0),"",AI19/$I$2) | AT19: =IF(OR($A19="",$I$2=0),"",(AI19+AJ19)/$I$2) | AU19: =IF($A19="","",IF(OR($AK19>=2,AND($AK19>0,$AQ19=""),AND($AK19>0,$AR19="")),"CRITICAL",IF(OR($AK19=1,AND(($AJ19)>0,$AQ19=""),AND(($AJ19)>0,$AR19=""),$AT19<0.95),"REVIEW","OK")))
A20: =IF('Employee Master'!A20="","",'Employee Master'!A20) | B20: =IF($A20="","",'Employee Master'!B20) | C20: =IF($A20="","",'Employee Master'!C20) | D20: P | E20: P | F20: P | G20: P | H20: P | I20: P | J20: P | K20: P | L20: P | M20: P | N20: P | O20: P | P20: P | Q20: P | R20: P | S20: P | T20: P | U20: P | V20: P | W20: P | X20: P | Y20: P | Z20: P | AA20: P | AB20: P | AC20: P | AD20: P | AE20: P | AF20: P | AG20: P | AH20: P | AI20: =IF($A20="","",COUNTIF($D20:$AH20,"P")) | AJ20: =IF($A20="","",COUNTIF($D20:$AH20,"AA")+COUNTIF($D20:$AH20,"SA")+COUNTIF($D20:$AH20,"EA")+COUNTIF($D20:$AH20,"OR")+COUNTIF($D20:$AH20,"WO")+COUNTIF($D20:$AH20,"H")) | AK20: =IF($A20="","",COUNTIF($D20:$AH20,"UA")) | AL20: =IF($A20="","",COUNTIF($D20:$AH20,"SA")) | AM20: =IF($A20="","",COUNTIF($D20:$AH20,"EA")) | AN20: =IF($A20="","",COUNTIF($D20:$AH20,"OR")) | AO20: =IF($A20="","",COUNTIF($D20:$AH20,"WO")) | AP20: =IF($A20="","",COUNTIF($D20:$AH20,"H")) | AS20: =IF(OR($A20="",$I$2=0),"",AI20/$I$2) | AT20: =IF(OR($A20="",$I$2=0),"",(AI20+AJ20)/$I$2) | AU20: =IF($A20="","",IF(OR($AK20>=2,AND($AK20>0,$AQ20=""),AND($AK20>0,$AR20="")),"CRITICAL",IF(OR($AK20=1,AND(($AJ20)>0,$AQ20=""),AND(($AJ20)>0,$AR20=""),$AT20<0.95),"REVIEW","OK")))
A21: =IF('Employee Master'!A21="","",'Employee Master'!A21) | B21: =IF($A21="","",'Employee Master'!B21) | C21: =IF($A21="","",'Employee Master'!C21) | D21: P | E21: P | F21: P | G21: P | H21: P | I21: P | J21: P | K21: P | L21: P | M21: P | N21: P | O21: P | P21: P | Q21: P | R21: UA | S21: UA | T21: UA | U21: UA | V21: UA | W21: UA | X21: UA | Y21: UA | Z21: UA | AA21: UA | AB21: UA | AC21: UA | AD21: UA | AE21: UA | AF21: UA | AG21: UA | AH21: UA | AI21: =IF($A21="","",COUNTIF($D21:$AH21,"P")) | AJ21: =IF($A21="","",COUNTIF($D21:$AH21,"AA")+COUNTIF($D21:$AH21,"SA")+COUNTIF($D21:$AH21,"EA")+COUNTIF($D21:$AH21,"OR")+COUNTIF($D21:$AH21,"WO")+COUNTIF($D21:$AH21,"H")) | AK21: =IF($A21="","",COUNTIF($D21:$AH21,"UA")) | AL21: =IF($A21="","",COUNTIF($D21:$AH21,"SA")) | AM21: =IF($A21="","",COUNTIF($D21:$AH21,"EA")) | AN21: =IF($A21="","",COUNTIF($D21:$AH21,"OR")) | AO21: =IF($A21="","",COUNTIF($D21:$AH21,"WO")) | AP21: =IF($A21="","",COUNTIF($D21:$AH21,"H")) | AS21: =IF(OR($A21="",$I$2=0),"",AI21/$I$2) | AT21: =IF(OR($A21="",$I$2=0),"",(AI21+AJ21)/$I$2) | AU21: =IF($A21="","",IF(OR($AK21>=2,AND($AK21>0,$AQ21=""),AND($AK21>0,$AR21="")),"CRITICAL",IF(OR($AK21=1,AND(($AJ21)>0,$AQ21=""),AND(($AJ21)>0,$AR21=""),$AT21<0.95),"REVIEW","OK")))
A22: =IF('Employee Master'!A22="","",'Employee Master'!A22) | B22: =IF($A22="","",'Employee Master'!B22) | C22: =IF($A22="","",'Employee Master'!C22) | D22: UA | E22: UA | F22: UA | G22: UA | H22: UA | I22: UA | J22: UA | K22: UA | L22: UA | M22: UA | N22: UA | O22: UA | P22: UA | Q22: UA | R22: UA | S22: UA | T22: UA | U22: UA | V22: UA | W22: UA | X22: UA | Y22: UA | Z22: UA | AA22: UA | AB22: UA | AC22: UA | AD22: UA | AE22: P | AF22: P | AG22: P | AH22: P | AI22: =IF($A22="","",COUNTIF($D22:$AH22,"P")) | AJ22: =IF($A22="","",COUNTIF($D22:$AH22,"AA")+COUNTIF($D22:$AH22,"SA")+COUNTIF($D22:$AH22,"EA")+COUNTIF($D22:$AH22,"OR")+COUNTIF($D22:$AH22,"WO")+COUNTIF($D22:$AH22,"H")) | AK22: =IF($A22="","",COUNTIF($D22:$AH22,"UA")) | AL22: =IF($A22="","",COUNTIF($D22:$AH22,"SA")) | AM22: =IF($A22="","",COUNTIF($D22:$AH22,"EA")) | AN22: =IF($A22="","",COUNTIF($D22:$AH22,"OR")) | AO22: =IF($A22="","",COUNTIF($D22:$AH22,"WO")) | AP22: =IF($A22="","",COUNTIF($D22:$AH22,"H")) | AS22: =IF(OR($A22="",$I$2=0),"",AI22/$I$2) | AT22: =IF(OR($A22="",$I$2=0),"",(AI22+AJ22)/$I$2) | AU22: =IF($A22="","",IF(OR($AK22>=2,AND($AK22>0,$AQ22=""),AND($AK22>0,$AR22="")),"CRITICAL",IF(OR($AK22=1,AND(($AJ22)>0,$AQ22=""),AND(($AJ22)>0,$AR22=""),$AT22<0.95),"REVIEW","OK")))
... A71: =IF('Employee Master'!A71="","",'Employee Master'!A71) | B71: =IF($A71="","",'Employee Master'!B71) | C71: =IF($A71="","",'Employee Master'!C71) | D71: P | E71: P | F71: P | G71: P | H71: P | I71: P | J71: P | K71: P | L71: P | M71: P | N71: P | O71: P | P71: P | Q71: P | R71: P | S71: P | T71: P | U71: P | V71: P | W71: P | X71: P | Y71: P | Z71: P | AA71: P | AB71: P | AC71: P | AD71: P | AE71: P | AF71: P | AG71: P | AH71: P | AI71: =IF($A71="","",COUNTIF($D71:$AH71,"P")) | AJ71: =IF($A71="","",COUNTIF($D71:$AH71,"AA")+COUNTIF($D71:$AH71,"SA")+COUNTIF($D71:$AH71,"EA")+COUNTIF($D71:$AH71,"OR")+COUNTIF($D71:$AH71,"WO")+COUNTIF($D71:$AH71,"H")) | AK71: =IF($A71="","",COUNTIF($D71:$AH71,"UA")) | AL71: =IF($A71="","",COUNTIF($D71:$AH71,"SA")) | AM71: =IF($A71="","",COUNTIF($D71:$AH71,"EA")) | AN71: =IF($A71="","",COUNTIF($D71:$AH71,"OR")) | AO71: =IF($A71="","",COUNTIF($D71:$AH71,"WO")) | AP71: =IF($A71="","",COUNTIF($D71:$AH71,"H")) | AS71: =IF(OR($A71="",$I$2=0),"",AI71/$I$2) | AT71: =IF(OR($A71="",$I$2=0),"",(AI71+AJ71)/$I$2) | AU71: =IF($A71="","",IF(OR($AK71>=2,AND($AK71>0,$AQ71=""),AND($AK71>0,$AR71="")),"CRITICAL",IF(OR($AK71=1,AND(($AJ71)>0,$AQ71=""),AND(($AJ71)>0,$AR71=""),$AT71<0.95),"REVIEW","OK")))
A72: =IF('Employee Master'!A72="","",'Employee Master'!A72) | B72: =IF($A72="","",'Employee Master'!B72) | C72: =IF($A72="","",'Employee Master'!C72) | AI72: =IF($A72="","",COUNTIF($D72:$AH72,"P")) | AJ72: =IF($A72="","",COUNTIF($D72:$AH72,"AA")+COUNTIF($D72:$AH72,"SA")+COUNTIF($D72:$AH72,"EA")+COUNTIF($D72:$AH72,"OR")+COUNTIF($D72:$AH72,"WO")+COUNTIF($D72:$AH72,"H")) | AK72: =IF($A72="","",COUNTIF($D72:$AH72,"UA")) | AL72: =IF($A72="","",COUNTIF($D72:$AH72,"SA")) | AM72: =IF($A72="","",COUNTIF($D72:$AH72,"EA")) | AN72: =IF($A72="","",COUNTIF($D72:$AH72,"OR")) | AO72: =IF($A72="","",COUNTIF($D72:$AH72,"WO")) | AP72: =IF($A72="","",COUNTIF($D72:$AH72,"H")) | AS72: =IF(OR($A72="",$I$2=0),"",AI72/$I$2) | AT72: =IF(OR($A72="",$I$2=0),"",(AI72+AJ72)/$I$2) | AU72: =IF($A72="","",IF(OR($AK72>=2,AND($AK72>0,$AQ72=""),AND($AK72>0,$AR72="")),"CRITICAL",IF(OR($AK72=1,AND(($AJ72)>0,$AQ72=""),AND(($AJ72)>0,$AR72=""),$AT72<0.95),"REVIEW","OK")))
A73: =IF('Employee Master'!A73="","",'Employee Master'!A73) | B73: =IF($A73="","",'Employee Master'!B73) | C73: =IF($A73="","",'Employee Master'!C73) | AI73: =IF($A73="","",COUNTIF($D73:$AH73,"P")) | AJ73: =IF($A73="","",COUNTIF($D73:$AH73,"AA")+COUNTIF($D73:$AH73,"SA")+COUNTIF($D73:$AH73,"EA")+COUNTIF($D73:$AH73,"OR")+COUNTIF($D73:$AH73,"WO")+COUNTIF($D73:$AH73,"H")) | AK73: =IF($A73="","",COUNTIF($D73:$AH73,"UA")) | AL73: =IF($A73="","",COUNTIF($D73:$AH73,"SA")) | AM73: =IF($A73="","",COUNTIF($D73:$AH73,"EA")) | AN73: =IF($A73="","",COUNTIF($D73:$AH73,"OR")) | AO73: =IF($A73="","",COUNTIF($D73:$AH73,"WO")) | AP73: =IF($A73="","",COUNTIF($D73:$AH73,"H")) | AS73: =IF(OR($A73="",$I$2=0),"",AI73/$I$2) | AT73: =IF(OR($A73="",$I$2=0),"",(AI73+AJ73)/$I$2) | AU73: =IF($A73="","",IF(OR($AK73>=2,AND($AK73>0,$AQ73=""),AND($AK73>0,$AR73="")),"CRITICAL",IF(OR($AK73=1,AND(($AJ73)>0,$AQ73=""),AND(($AJ73)>0,$AR73=""),$AT73<0.95),"REVIEW","OK")))
A74: =IF('Employee Master'!A74="","",'Employee Master'!A74) | B74: =IF($A74="","",'Employee Master'!B74) | C74: =IF($A74="","",'Employee Master'!C74) | AI74: =IF($A74="","",COUNTIF($D74:$AH74,"P")) | AJ74: =IF($A74="","",COUNTIF($D74:$AH74,"AA")+COUNTIF($D74:$AH74,"SA")+COUNTIF($D74:$AH74,"EA")+COUNTIF($D74:$AH74,"OR")+COUNTIF($D74:$AH74,"WO")+COUNTIF($D74:$AH74,"H")) | AK74: =IF($A74="","",COUNTIF($D74:$AH74,"UA")) | AL74: =IF($A74="","",COUNTIF($D74:$AH74,"SA")) | AM74: =IF($A74="","",COUNTIF($D74:$AH74,"EA")) | AN74: =IF($A74="","",COUNTIF($D74:$AH74,"OR")) | AO74: =IF($A74="","",COUNTIF($D74:$AH74,"WO")) | AP74: =IF($A74="","",COUNTIF($D74:$AH74,"H")) | AS74: =IF(OR($A74="",$I$2=0),"",AI74/$I$2) | AT74: =IF(OR($A74="",$I$2=0),"",(AI74+AJ74)/$I$2) | AU74: =IF($A74="","",IF(OR($AK74>=2,AND($AK74>0,$AQ74=""),AND($AK74>0,$AR74="")),"CRITICAL",IF(OR($AK74=1,AND(($AJ74)>0,$AQ74=""),AND(($AJ74)>0,$AR74=""),$AT74<0.95),"REVIEW","OK")))
A75: =IF('Employee Master'!A75="","",'Employee Master'!A75) | B75: =IF($A75="","",'Employee Master'!B75) | C75: =IF($A75="","",'Employee Master'!C75) | AI75: =IF($A75="","",COUNTIF($D75:$AH75,"P")) | AJ75: =IF($A75="","",COUNTIF($D75:$AH75,"AA")+COUNTIF($D75:$AH75,"SA")+COUNTIF($D75:$AH75,"EA")+COUNTIF($D75:$AH75,"OR")+COUNTIF($D75:$AH75,"WO")+COUNTIF($D75:$AH75,"H")) | AK75: =IF($A75="","",COUNTIF($D75:$AH75,"UA")) | AL75: =IF($A75="","",COUNTIF($D75:$AH75,"SA")) | AM75: =IF($A75="","",COUNTIF($D75:$AH75,"EA")) | AN75: =IF($A75="","",COUNTIF($D75:$AH75,"OR")) | AO75: =IF($A75="","",COUNTIF($D75:$AH75,"WO")) | AP75: =IF($A75="","",COUNTIF($D75:$AH75,"H")) | AS75: =IF(OR($A75="",$I$2=0),"",AI75/$I$2) | AT75: =IF(OR($A75="",$I$2=0),"",(AI75+AJ75)/$I$2) | AU75: =IF($A75="","",IF(OR($AK75>=2,AND($AK75>0,$AQ75=""),AND($AK75>0,$AR75="")),"CRITICAL",IF(OR($AK75=1,AND(($AJ75)>0,$AQ75=""),AND(($AJ75)>0,$AR75=""),$AT75<0.95),"REVIEW","OK")))
A76: =IF('Employee Master'!A76="","",'Employee Master'!A76) | B76: =IF($A76="","",'Employee Master'!B76) | C76: =IF($A76="","",'Employee Master'!C76) | AI76: =IF($A76="","",COUNTIF($D76:$AH76,"P")) | AJ76: =IF($A76="","",COUNTIF($D76:$AH76,"AA")+COUNTIF($D76:$AH76,"SA")+COUNTIF($D76:$AH76,"EA")+COUNTIF($D76:$AH76,"OR")+COUNTIF($D76:$AH76,"WO")+COUNTIF($D76:$AH76,"H")) | AK76: =IF($A76="","",COUNTIF($D76:$AH76,"UA")) | AL76: =IF($A76="","",COUNTIF($D76:$AH76,"SA")) | AM76: =IF($A76="","",COUNTIF($D76:$AH76,"EA")) | AN76: =IF($A76="","",COUNTIF($D76:$AH76,"OR")) | AO76: =IF($A76="","",COUNTIF($D76:$AH76,"WO")) | AP76: =IF($A76="","",COUNTIF($D76:$AH76,"H")) | AS76: =IF(OR($A76="",$I$2=0),"",AI76/$I$2) | AT76: =IF(OR($A76="",$I$2=0),"",(AI76+AJ76)/$I$2) | AU76: =IF($A76="","",IF(OR($AK76>=2,AND($AK76>0,$AQ76=""),AND($AK76>0,$AR76="")),"CRITICAL",IF(OR($AK76=1,AND(($AJ76)>0,$AQ76=""),AND(($AJ76)>0,$AR76=""),$AT76<0.95),"REVIEW","OK")))
A77: =IF('Employee Master'!A77="","",'Employee Master'!A77) | B77: =IF($A77="","",'Employee Master'!B77) | C77: =IF($A77="","",'Employee Master'!C77) | AI77: =IF($A77="","",COUNTIF($D77:$AH77,"P")) | AJ77: =IF($A77="","",COUNTIF($D77:$AH77,"AA")+COUNTIF($D77:$AH77,"SA")+COUNTIF($D77:$AH77,"EA")+COUNTIF($D77:$AH77,"OR")+COUNTIF($D77:$AH77,"WO")+COUNTIF($D77:$AH77,"H")) | AK77: =IF($A77="","",COUNTIF($D77:$AH77,"UA")) | AL77: =IF($A77="","",COUNTIF($D77:$AH77,"SA")) | AM77: =IF($A77="","",COUNTIF($D77:$AH77,"EA")) | AN77: =IF($A77="","",COUNTIF($D77:$AH77,"OR")) | AO77: =IF($A77="","",COUNTIF($D77:$AH77,"WO")) | AP77: =IF($A77="","",COUNTIF($D77:$AH77,"H")) | AS77: =IF(OR($A77="",$I$2=0),"",AI77/$I$2) | AT77: =IF(OR($A77="",$I$2=0),"",(AI77+AJ77)/$I$2) | AU77: =IF($A77="","",IF(OR($AK77>=2,AND($AK77>0,$AQ77=""),AND($AK77>0,$AR77="")),"CRITICAL",IF(OR($AK77=1,AND(($AJ77)>0,$AQ77=""),AND(($AJ77)>0,$AR77=""),$AT77<0.95),"REVIEW","OK")))
A78: =IF('Employee Master'!A78="","",'Employee Master'!A78) | B78: =IF($A78="","",'Employee Master'!B78) | C78: =IF($A78="","",'Employee Master'!C78) | AI78: =IF($A78="","",COUNTIF($D78:$AH78,"P")) | AJ78: =IF($A78="","",COUNTIF($D78:$AH78,"AA")+COUNTIF($D78:$AH78,"SA")+COUNTIF($D78:$AH78,"EA")+COUNTIF($D78:$AH78,"OR")+COUNTIF($D78:$AH78,"WO")+COUNTIF($D78:$AH78,"H")) | AK78: =IF($A78="","",COUNTIF($D78:$AH78,"UA")) | AL78: =IF($A78="","",COUNTIF($D78:$AH78,"SA")) | AM78: =IF($A78="","",COUNTIF($D78:$AH78,"EA")) | AN78: =IF($A78="","",COUNTIF($D78:$AH78,"OR")) | AO78: =IF($A78="","",COUNTIF($D78:$AH78,"WO")) | AP78: =IF($A78="","",COUNTIF($D78:$AH78,"H")) | AS78: =IF(OR($A78="",$I$2=0),"",AI78/$I$2) | AT78: =IF(OR($A78="",$I$2=0),"",(AI78+AJ78)/$I$2) | AU78: =IF($A78="","",IF(OR($AK78>=2,AND($AK78>0,$AQ78=""),AND($AK78>0,$AR78="")),"CRITICAL",IF(OR($AK78=1,AND(($AJ78)>0,$AQ78=""),AND(($AJ78)>0,$AR78=""),$AT78<0.95),"REVIEW","OK")))
A79: =IF('Employee Master'!A79="","",'Employee Master'!A79) | B79: =IF($A79="","",'Employee Master'!B79) | C79: =IF($A79="","",'Employee Master'!C79) | AI79: =IF($A79="","",COUNTIF($D79:$AH79,"P")) | AJ79: =IF($A79="","",COUNTIF($D79:$AH79,"AA")+COUNTIF($D79:$AH79,"SA")+COUNTIF($D79:$AH79,"EA")+COUNTIF($D79:$AH79,"OR")+COUNTIF($D79:$AH79,"WO")+COUNTIF($D79:$AH79,"H")) | AK79: =IF($A79="","",COUNTIF($D79:$AH79,"UA")) | AL79: =IF($A79="","",COUNTIF($D79:$AH79,"SA")) | AM79: =IF($A79="","",COUNTIF($D79:$AH79,"EA")) | AN79: =IF($A79="","",COUNTIF($D79:$AH79,"OR")) | AO79: =IF($A79="","",COUNTIF($D79:$AH79,"WO")) | AP79: =IF($A79="","",COUNTIF($D79:$AH79,"H")) | AS79: =IF(OR($A79="",$I$2=0),"",AI79/$I$2) | AT79: =IF(OR($A79="",$I$2=0),"",(AI79+AJ79)/$I$2) | AU79: =IF($A79="","",IF(OR($AK79>=2,AND($AK79>0,$AQ79=""),AND($AK79>0,$AR79="")),"CRITICAL",IF(OR($AK79=1,AND(($AJ79)>0,$AQ79=""),AND(($AJ79)>0,$AR79=""),$AT79<0.95),"REVIEW","OK")))
A80: =IF('Employee Master'!A80="","",'Employee Master'!A80) | B80: =IF($A80="","",'Employee Master'!B80) | C80: =IF($A80="","",'Employee Master'!C80) | AI80: =IF($A80="","",COUNTIF($D80:$AH80,"P")) | AJ80: =IF($A80="","",COUNTIF($D80:$AH80,"AA")+COUNTIF($D80:$AH80,"SA")+COUNTIF($D80:$AH80,"EA")+COUNTIF($D80:$AH80,"OR")+COUNTIF($D80:$AH80,"WO")+COUNTIF($D80:$AH80,"H")) | AK80: =IF($A80="","",COUNTIF($D80:$AH80,"UA")) | AL80: =IF($A80="","",COUNTIF($D80:$AH80,"SA")) | AM80: =IF($A80="","",COUNTIF($D80:$AH80,"EA")) | AN80: =IF($A80="","",COUNTIF($D80:$AH80,"OR")) | AO80: =IF($A80="","",COUNTIF($D80:$AH80,"WO")) | AP80: =IF($A80="","",COUNTIF($D80:$AH80,"H")) | AS80: =IF(OR($A80="",$I$2=0),"",AI80/$I$2) | AT80: =IF(OR($A80="",$I$2=0),"",(AI80+AJ80)/$I$2) | AU80: =IF($A80="","",IF(OR($AK80>=2,AND($AK80>0,$AQ80=""),AND($AK80>0,$AR80="")),"CRITICAL",IF(OR($AK80=1,AND(($AJ80)>0,$AQ80=""),AND(($AJ80)>0,$AR80=""),$AT80<0.95),"REVIEW","OK")))
A81: =IF('Employee Master'!A81="","",'Employee Master'!A81) | B81: =IF($A81="","",'Employee Master'!B81) | C81: =IF($A81="","",'Employee Master'!C81) | AI81: =IF($A81="","",COUNTIF($D81:$AH81,"P")) | AJ81: =IF($A81="","",COUNTIF($D81:$AH81,"AA")+COUNTIF($D81:$AH81,"SA")+COUNTIF($D81:$AH81,"EA")+COUNTIF($D81:$AH81,"OR")+COUNTIF($D81:$AH81,"WO")+COUNTIF($D81:$AH81,"H")) | AK81: =IF($A81="","",COUNTIF($D81:$AH81,"UA")) | AL81: =IF($A81="","",COUNTIF($D81:$AH81,"SA")) | AM81: =IF($A81="","",COUNTIF($D81:$AH81,"EA")) | AN81: =IF($A81="","",COUNTIF($D81:$AH81,"OR")) | AO81: =IF($A81="","",COUNTIF($D81:$AH81,"WO")) | AP81: =IF($A81="","",COUNTIF($D81:$AH81,"H")) | AS81: =IF(OR($A81="",$I$2=0),"",AI81/$I$2) | AT81: =IF(OR($A81="",$I$2=0),"",(AI81+AJ81)/$I$2) | AU81: =IF($A81="","",IF(OR($AK81>=2,AND($AK81>0,$AQ81=""),AND($AK81>0,$AR81="")),"CRITICAL",IF(OR($AK81=1,AND(($AJ81)>0,$AQ81=""),AND(($AJ81)>0,$AR81=""),$AT81<0.95),"REVIEW","OK")))
A82: =IF('Employee Master'!A82="","",'Employee Master'!A82) | B82: =IF($A82="","",'Employee Master'!B82) | C82: =IF($A82="","",'Employee Master'!C82) | AI82: =IF($A82="","",COUNTIF($D82:$AH82,"P")) | AJ82: =IF($A82="","",COUNTIF($D82:$AH82,"AA")+COUNTIF($D82:$AH82,"SA")+COUNTIF($D82:$AH82,"EA")+COUNTIF($D82:$AH82,"OR")+COUNTIF($D82:$AH82,"WO")+COUNTIF($D82:$AH82,"H")) | AK82: =IF($A82="","",COUNTIF($D82:$AH82,"UA")) | AL82: =IF($A82="","",COUNTIF($D82:$AH82,"SA")) | AM82: =IF($A82="","",COUNTIF($D82:$AH82,"EA")) | AN82: =IF($A82="","",COUNTIF($D82:$AH82,"OR")) | AO82: =IF($A82="","",COUNTIF($D82:$AH82,"WO")) | AP82: =IF($A82="","",COUNTIF($D82:$AH82,"H")) | AS82: =IF(OR($A82="",$I$2=0),"",AI82/$I$2) | AT82: =IF(OR($A82="",$I$2=0),"",(AI82+AJ82)/$I$2) | AU82: =IF($A82="","",IF(OR($AK82>=2,AND($AK82>0,$AQ82=""),AND($AK82>0,$AR82="")),"CRITICAL",IF(OR($AK82=1,AND(($AJ82)>0,$AQ82=""),AND(($AJ82)>0,$AR82=""),$AT82<0.95),"REVIEW","OK")))
A83: =IF('Employee Master'!A83="","",'Employee Master'!A83) | B83: =IF($A83="","",'Employee Master'!B83) | C83: =IF($A83="","",'Employee Master'!C83) | AI83: =IF($A83="","",COUNTIF($D83:$AH83,"P")) | AJ83: =IF($A83="","",COUNTIF($D83:$AH83,"AA")+COUNTIF($D83:$AH83,"SA")+COUNTIF($D83:$AH83,"EA")+COUNTIF($D83:$AH83,"OR")+COUNTIF($D83:$AH83,"WO")+COUNTIF($D83:$AH83,"H")) | AK83: =IF($A83="","",COUNTIF($D83:$AH83,"UA")) | AL83: =IF($A83="","",COUNTIF($D83:$AH83,"SA")) | AM83: =IF($A83="","",COUNTIF($D83:$AH83,"EA")) | AN83: =IF($A83="","",COUNTIF($D83:$AH83,"OR")) | AO83: =IF($A83="","",COUNTIF($D83:$AH83,"WO")) | AP83: =IF($A83="","",COUNTIF($D83:$AH83,"H")) | AS83: =IF(OR($A83="",$I$2=0),"",AI83/$I$2) | AT83: =IF(OR($A83="",$I$2=0),"",(AI83+AJ83)/$I$2) | AU83: =IF($A83="","",IF(OR($AK83>=2,AND($AK83>0,$AQ83=""),AND($AK83>0,$AR83="")),"CRITICAL",IF(OR($AK83=1,AND(($AJ83)>0,$AQ83=""),AND(($AJ83)>0,$AR83=""),$AT83<0.95),"REVIEW","OK")))
... A107: =IF('Employee Master'!A107="","",'Employee Master'!A107) | B107: =IF($A107="","",'Employee Master'!B107) | C107: =IF($A107="","",'Employee Master'!C107) | AI107: =IF($A107="","",COUNTIF($D107:$AH107,"P")) | AJ107: =IF($A107="","",COUNTIF($D107:$AH107,"AA")+COUNTIF($D107:$AH107,"SA")+COUNTIF($D107:$AH107,"EA")+COUNTIF($D107:$AH107,"OR")+COUNTIF($D107:$AH107,"WO")+COUNTIF($D107:$AH107,"H")) | AK107: =IF($A107="","",COUNTIF($D107:$AH107,"UA")) | AL107: =IF($A107="","",COUNTIF($D107:$AH107,"SA")) | AM107: =IF($A107="","",COUNTIF($D107:$AH107,"EA")) | AN107: =IF($A107="","",COUNTIF($D107:$AH107,"OR")) | AO107: =IF($A107="","",COUNTIF($D107:$AH107,"WO")) | AP107: =IF($A107="","",COUNTIF($D107:$AH107,"H")) | AS107: =IF(OR($A107="",$I$2=0),"",AI107/$I$2) | AT107: =IF(OR($A107="",$I$2=0),"",(AI107+AJ107)/$I$2) | AU107: =IF($A107="","",IF(OR($AK107>=2,AND($AK107>0,$AQ107=""),AND($AK107>0,$AR107="")),"CRITICAL",IF(OR($AK107=1,AND(($AJ107)>0,$AQ107=""),AND(($AJ107)>0,$AR107=""),$AT107<0.95),"REVIEW","OK")))

Sheet Feb
A1: February Monthly Staff Attendance Master Register
A2: Month Start | B2: =DATE('Control Panel'!$B$3,2,1) | D2: Reporting Month | E2: =TEXT($B$2,"mmmm yyyy") | H2: Working Days | I2: =COUNTA($D$4:$AH$4) | K2: Active Employees | L2: =COUNTIFS('Employee Master'!A8:A107,"?*",'Employee Master'!D8:D107,"Active") | AW2: Status | AX2: Meaning
A3: Enter daily statuses using: P, AA, UA, SA, EA, OR, WO, H. All calendar days from the 1st to the last day of the month are treated as work days, including weekends and public holidays, unless an absence status is entered. | AW3: P | AX3: Present
D4: =IF(COLUMN()-3<=DAY(DATE(YEAR($B$2),MONTH($B$2)+1,0)),DATE(YEAR($B$2),MONTH($B$2),COLUMN()-3),"") | E4: =IF(COLUMN()-3<=DAY(DATE(YEAR($B$2),MONTH($B$2)+1,0)),DATE(YEAR($B$2),MONTH($B$2),COLUMN()-3),"") | F4: =IF(COLUMN()-3<=DAY(DATE(YEAR($B$2),MONTH($B$2)+1,0)),DATE(YEAR($B$2),MONTH($B$2),COLUMN()-3),"") | G4: =IF(COLUMN()-3<=DAY(DATE(YEAR($B$2),MONTH($B$2)+1,0)),DATE(YEAR($B$2),MONTH($B$2),COLUMN()-3),"") | H4: =IF(COLUMN()-3<=DAY(DATE(YEAR($B$2),MONTH($B$2)+1,0)),DATE(YEAR($B$2),MONTH($B$2),COLUMN()-3),"") | I4: =IF(COLUMN()-3<=DAY(DATE(YEAR($B$2),MONTH($B$2)+1,0)),DATE(YEAR($B$2),MONTH($B$2),COLUMN()-3),"") | J4: =IF(COLUMN()-3<=DAY(DATE(YEAR($B$2),MONTH($B$2)+1,0)),DATE(YEAR($B$2),MONTH($B$2),COLUMN()-3),"") | K4: =IF(COLUMN()-3<=DAY(DATE(YEAR($B$2),MONTH($B$2)+1,0)),DATE(YEAR($B$2),MONTH($B$2),COLUMN()-3),"") | ... AH4: =IF(COLUMN()-3<=DAY(DATE(YEAR($B$2),MONTH($B$2)+1,0)),DATE(YEAR($B$2),MONTH($B$2),COLUMN()-3),"") | AV4: AA | AW4: Authorised Attendance | AX4: Authorised Attendance
A5: Employee Details | D5: Daily Attendance Status | AI5: Monthly Summary & Forensic Review | AV5: UA | AW5: Unauthorised Attendance | AX5: Unauthorised Attendance
A6: Employee ID | B6: Employee Name | C6: Reported To | D6: =IF(D$4="","",DAY(D$4)) | E6: =IF(E$4="","",DAY(E$4)) | F6: =IF(F$4="","",DAY(F$4)) | G6: =IF(G$4="","",DAY(G$4)) | H6: =IF(H$4="","",DAY(H$4)) | I6: =IF(I$4="","",DAY(I$4)) | J6: =IF(J$4="","",DAY(J$4)) | K6: =IF(K$4="","",DAY(K$4)) | ... AH6: =IF(AH$4="","",DAY(AH$4)) | AI6: Present | AJ6: Authorised Absence | AK6: Unauthorised Absence | AL6: Sickness Absence | AM6: Emergency Absence | AN6: Other Reason | AO6: Weekend Off | AP6: Holiday | AQ6: Absence Reason | AR6: Remarks | AS6: Attendance % | AT6: Compliance % | AU6: Forensic Flag | AV6: SA | AW6: Sick Absence | AX6: Sick Absence
D7: =IF(D$4="","","WD") | E7: =IF(E$4="","","WD") | F7: =IF(F$4="","","WD") | G7: =IF(G$4="","","WD") | H7: =IF(H$4="","","WD") | I7: =IF(I$4="","","WD") | J7: =IF(J$4="","","WD") | K7: =IF(K$4="","","WD") | ... AH7: =IF(AH$4="","","WD") | AV7: EA | AW7: Emergency Absence | AX7: Emergency Absence
A8: =IF('Employee Master'!A8="","",'Employee Master'!A8) | B8: =IF($A8="","",'Employee Master'!B8) | C8: =IF($A8="","",'Employee Master'!C8) | D8: P | E8: UA | F8: UA | G8: UA | H8: UA | I8: UA | J8: UA | K8: UA | L8: UA | M8: UA | N8: UA | O8: UA | P8: UA | Q8: UA | R8: UA | S8: UA | T8: UA | U8: UA | V8: UA | W8: UA | X8: UA | Y8: UA | Z8: UA | AA8: UA | AB8: UA | AC8: UA | AD8: UA | AE8: UA | AI8: =IF($A8="","",COUNTIF($D8:$AH8,"P")) | AJ8: =IF($A8="","",COUNTIF($D8:$AH8,"AA")+COUNTIF($D8:$AH8,"SA")+COUNTIF($D8:$AH8,"EA")+COUNTIF($D8:$AH8,"OR")+COUNTIF($D8:$AH8,"WO")+COUNTIF($D8:$AH8,"H")) | AK8: =IF($A8="","",COUNTIF($D8:$AH8,"UA")) | AL8: =IF($A8="","",COUNTIF($D8:$AH8,"SA")) | AM8: =IF($A8="","",COUNTIF($D8:$AH8,"EA")) | AN8: =IF($A8="","",COUNTIF($D8:$AH8,"OR")) | AO8: =IF($A8="","",COUNTIF($D8:$AH8,"WO")) | AP8: =IF($A8="","",COUNTIF($D8:$AH8,"H")) | AS8: =IF(OR($A8="",$I$2=0),"",AI8/$I$2) | AT8: =IF(OR($A8="",$I$2=0),"",(AI8+AJ8)/$I$2) | AU8: =IF($A8="","",IF(OR($AK8>=2,AND($AK8>0,$AQ8=""),AND($AK8>0,$AR8="")),"CRITICAL",IF(OR($AK8=1,AND(($AJ8)>0,$AQ8=""),AND(($AJ8)>0,$AR8=""),$AT8<0.95),"REVIEW","OK"))) | AV8: OR | AW8: Other Reason | AX8: Other Reason
A9: =IF('Employee Master'!A9="","",'Employee Master'!A9) | B9: =IF($A9="","",'Employee Master'!B9) | C9: =IF($A9="","",'Employee Master'!C9) | D9: UA | E9: UA | F9: P | G9: P | H9: P | I9: P | J9: P | K9: P | L9: P | M9: P | N9: P | O9: P | P9: P | Q9: P | R9: P | S9: P | T9: P | U9: P | V9: P | W9: P | X9: P | Y9: P | Z9: P | AA9: P | AB9: P | AC9: P | AD9: P | AE9: P | AI9: =IF($A9="","",COUNTIF($D9:$AH9,"P")) | AJ9: =IF($A9="","",COUNTIF($D9:$AH9,"AA")+COUNTIF($D9:$AH9,"SA")+COUNTIF($D9:$AH9,"EA")+COUNTIF($D9:$AH9,"OR")+COUNTIF($D9:$AH9,"WO")+COUNTIF($D9:$AH9,"H")) | AK9: =IF($A9="","",COUNTIF($D9:$AH9,"UA")) | AL9: =IF($A9="","",COUNTIF($D9:$AH9,"SA")) | AM9: =IF($A9="","",COUNTIF($D9:$AH9,"EA")) | AN9: =IF($A9="","",COUNTIF($D9:$AH9,"OR")) | AO9: =IF($A9="","",COUNTIF($D9:$AH9,"WO")) | AP9: =IF($A9="","",COUNTIF($D9:$AH9,"H")) | AS9: =IF(OR($A9="",$I$2=0),"",AI9/$I$2) | AT9: =IF(OR($A9="",$I$2=0),"",(AI9+AJ9)/$I$2) | AU9: =IF($A9="","",IF(OR($AK9>=2,AND($AK9>0,$AQ9=""),AND($AK9>0,$AR9="")),"CRITICAL",IF(OR($AK9=1,AND(($AJ9)>0,$AQ9=""),AND(($AJ9)>0,$AR9=""),$AT9<0.95),"REVIEW","OK"))) | AV9: WO | AW9: Weekend Off / Approved Rest Day | AX9: Weekend Off
A10: =IF('Employee Master'!A10="","",'Employee Master'!A10) | B10: =IF($A10="","",'Employee Master'!B10) | C10: =IF($A10="","",'Employee Master'!C10) | D10: P | E10: P | F10: P | G10: P | H10: P | I10: P | J10: P | K10: P | L10: P | M10: P | N10: P | O10: P | P10: P | Q10: UA | R10: UA | S10: UA | T10: UA | U10: UA | V10: UA | W10: UA | X10: UA | Y10: UA | Z10: P | AA10: P | AB10: P | AC10: P | AD10: P | AE10: P | AI10: =IF($A10="","",COUNTIF($D10:$AH10,"P")) | AJ10: =IF($A10="","",COUNTIF($D10:$AH10,"AA")+COUNTIF($D10:$AH10,"SA")+COUNTIF($D10:$AH10,"EA")+COUNTIF($D10:$AH10,"OR")+COUNTIF($D10:$AH10,"WO")+COUNTIF($D10:$AH10,"H")) | AK10: =IF($A10="","",COUNTIF($D10:$AH10,"UA")) | AL10: =IF($A10="","",COUNTIF($D10:$AH10,"SA")) | AM10: =IF($A10="","",COUNTIF($D10:$AH10,"EA")) | AN10: =IF($A10="","",COUNTIF($D10:$AH10,"OR")) | AO10: =IF($A10="","",COUNTIF($D10:$AH10,"WO")) | AP10: =IF($A10="","",COUNTIF($D10:$AH10,"H")) | AS10: =IF(OR($A10="",$I$2=0),"",AI10/$I$2) | AT10: =IF(OR($A10="",$I$2=0),"",(AI10+AJ10)/$I$2) | AU10: =IF($A10="","",IF(OR($AK10>=2,AND($AK10>0,$AQ10=""),AND($AK10>0,$AR10="")),"CRITICAL",IF(OR($AK10=1,AND(($AJ10)>0,$AQ10=""),AND(($AJ10)>0,$AR10=""),$AT10<0.95),"REVIEW","OK"))) | AV10: H | AW10: Holiday / Approved Leave | AX10: Holiday
A11: =IF('Employee Master'!A11="","",'Employee Master'!A11) | B11: =IF($A11="","",'Employee Master'!B11) | C11: =IF($A11="","",'Employee Master'!C11) | D11: UA | E11: UA | F11: UA | G11: UA | H11: UA | I11: UA | J11: UA | K11: UA | L11: UA | M11: UA | N11: UA | O11: UA | P11: UA | Q11: UA | R11: UA | S11: UA | T11: UA | U11: UA | V11: UA | W11: UA | X11: UA | Y11: UA | Z11: P | AA11: P | AB11: P | AC11: P | AD11: P | AE11: P | AI11: =IF($A11="","",COUNTIF($D11:$AH11,"P")) | AJ11: =IF($A11="","",COUNTIF($D11:$AH11,"AA")+COUNTIF($D11:$AH11,"SA")+COUNTIF($D11:$AH11,"EA")+COUNTIF($D11:$AH11,"OR")+COUNTIF($D11:$AH11,"WO")+COUNTIF($D11:$AH11,"H")) | AK11: =IF($A11="","",COUNTIF($D11:$AH11,"UA")) | AL11: =IF($A11="","",COUNTIF($D11:$AH11,"SA")) | AM11: =IF($A11="","",COUNTIF($D11:$AH11,"EA")) | AN11: =IF($A11="","",COUNTIF($D11:$AH11,"OR")) | AO11: =IF($A11="","",COUNTIF($D11:$AH11,"WO")) | AP11: =IF($A11="","",COUNTIF($D11:$AH11,"H")) | AS11: =IF(OR($A11="",$I$2=0),"",AI11/$I$2) | AT11: =IF(OR($A11="",$I$2=0),"",(AI11+AJ11)/$I$2) | AU11: =IF($A11="","",IF(OR($AK11>=2,AND($AK11>0,$AQ11=""),AND($AK11>0,$AR11="")),"CRITICAL",IF(OR($AK11=1,AND(($AJ11)>0,$AQ11=""),AND(($AJ11)>0,$AR11=""),$AT11<0.95),"REVIEW","OK")))
A12: =IF('Employee Master'!A12="","",'Employee Master'!A12) | B12: =IF($A12="","",'Employee Master'!B12) | C12: =IF($A12="","",'Employee Master'!C12) | D12: P | E12: UA | F12: UA | G12: UA | H12: UA | I12: UA | J12: UA | K12: UA | L12: UA | M12: UA | N12: UA | O12: UA | P12: UA | Q12: UA | R12: UA | S12: UA | T12: UA | U12: UA | V12: UA | W12: UA | X12: UA | Y12: UA | Z12: UA | AA12: UA | AB12: UA | AC12: P | AD12: P | AE12: P | AI12: =IF($A12="","",COUNTIF($D12:$AH12,"P")) | AJ12: =IF($A12="","",COUNTIF($D12:$AH12,"AA")+COUNTIF($D12:$AH12,"SA")+COUNTIF($D12:$AH12,"EA")+COUNTIF($D12:$AH12,"OR")+COUNTIF($D12:$AH12,"WO")+COUNTIF($D12:$AH12,"H")) | AK12: =IF($A12="","",COUNTIF($D12:$AH12,"UA")) | AL12: =IF($A12="","",COUNTIF($D12:$AH12,"SA")) | AM12: =IF($A12="","",COUNTIF($D12:$AH12,"EA")) | AN12: =IF($A12="","",COUNTIF($D12:$AH12,"OR")) | AO12: =IF($A12="","",COUNTIF($D12:$AH12,"WO")) | AP12: =IF($A12="","",COUNTIF($D12:$AH12,"H")) | AS12: =IF(OR($A12="",$I$2=0),"",AI12/$I$2) | AT12: =IF(OR($A12="",$I$2=0),"",(AI12+AJ12)/$I$2) | AU12: =IF($A12="","",IF(OR($AK12>=2,AND($AK12>0,$AQ12=""),AND($AK12>0,$AR12="")),"CRITICAL",IF(OR($AK12=1,AND(($AJ12)>0,$AQ12=""),AND(($AJ12)>0,$AR12=""),$AT12<0.95),"REVIEW","OK")))
A13: =IF('Employee Master'!A13="","",'Employee Master'!A13) | B13: =IF($A13="","",'Employee Master'!B13) | C13: =IF($A13="","",'Employee Master'!C13) | D13: P | E13: P | F13: P | G13: P | H13: P | I13: P | J13: P | K13: P | L13: P | M13: P | N13: P | O13: P | P13: P | Q13: P | R13: P | S13: P | T13: P | U13: P | V13: P | W13: P | X13: P | Y13: P | Z13: P | AA13: P | AB13: P | AC13: P | AD13: P | AE13: P | AI13: =IF($A13="","",COUNTIF($D13:$AH13,"P")) | AJ13: =IF($A13="","",COUNTIF($D13:$AH13,"AA")+COUNTIF($D13:$AH13,"SA")+COUNTIF($D13:$AH13,"EA")+COUNTIF($D13:$AH13,"OR")+COUNTIF($D13:$AH13,"WO")+COUNTIF($D13:$AH13,"H")) | AK13: =IF($A13="","",COUNTIF($D13:$AH13,"UA")) | AL13: =IF($A13="","",COUNTIF($D13:$AH13,"SA")) | AM13: =IF($A13="","",COUNTIF($D13:$AH13,"EA")) | AN13: =IF($A13="","",COUNTIF($D13:$AH13,"OR")) | AO13: =IF($A13="","",COUNTIF($D13:$AH13,"WO")) | AP13: =IF($A13="","",COUNTIF($D13:$AH13,"H")) | AS13: =IF(OR($A13="",$I$2=0),"",AI13/$I$2) | AT13: =IF(OR($A13="",$I$2=0),"",(AI13+AJ13)/$I$2) | AU13: =IF($A13="","",IF(OR($AK13>=2,AND($AK13>0,$AQ13=""),AND($AK13>0,$AR13="")),"CRITICAL",IF(OR($AK13=1,AND(($AJ13)>0,$AQ13=""),AND(($AJ13)>0,$AR13=""),$AT13<0.95),"REVIEW","OK")))
A14: =IF('Employee Master'!A14="","",'Employee Master'!A14) | B14: =IF($A14="","",'Employee Master'!B14) | C14: =IF($A14="","",'Employee Master'!C14) | D14: P | E14: P | F14: P | G14: P | H14: P | I14: P | J14: P | K14: P | L14: P | M14: P | N14: P | O14: P | P14: P | Q14: P | R14: P | S14: P | T14: P | U14: P | V14: P | W14: P | X14: P | Y14: P | Z14: P | AA14: P | AB14: P | AC14: P | AD14: P | AE14: P | AI14: =IF($A14="","",COUNTIF($D14:$AH14,"P")) | AJ14: =IF($A14="","",COUNTIF($D14:$AH14,"AA")+COUNTIF($D14:$AH14,"SA")+COUNTIF($D14:$AH14,"EA")+COUNTIF($D14:$AH14,"OR")+COUNTIF($D14:$AH14,"WO")+COUNTIF($D14:$AH14,"H")) | AK14: =IF($A14="","",COUNTIF($D14:$AH14,"UA")) | AL14: =IF($A14="","",COUNTIF($D14:$AH14,"SA")) | AM14: =IF($A14="","",COUNTIF($D14:$AH14,"EA")) | AN14: =IF($A14="","",COUNTIF($D14:$AH14,"OR")) | AO14: =IF($A14="","",COUNTIF($D14:$AH14,"WO")) | AP14: =IF($A14="","",COUNTIF($D14:$AH14,"H")) | AS14: =IF(OR($A14="",$I$2=0),"",AI14/$I$2) | AT14: =IF(OR($A14="",$I$2=0),"",(AI14+AJ14)/$I$2) | AU14: =IF($A14="","",IF(OR($AK14>=2,AND($AK14>0,$AQ14=""),AND($AK14>0,$AR14="")),"CRITICAL",IF(OR($AK14=1,AND(($AJ14)>0,$AQ14=""),AND(($AJ14)>0,$AR14=""),$AT14<0.95),"REVIEW","OK")))
A15: =IF('Employee Master'!A15="","",'Employee Master'!A15) | B15: =IF($A15="","",'Employee Master'!B15) | C15: =IF($A15="","",'Employee Master'!C15) | D15: P | E15: P | F15: P | G15: P | H15: P | I15: P | J15: P | K15: P | L15: UA | M15: UA | N15: UA | O15: UA | P15: UA | Q15: UA | R15: UA | S15: UA | T15: UA | U15: UA | V15: UA | W15: UA | X15: P | Y15: P | Z15: P | AA15: P | AB15: P | AC15: P | AD15: P | AE15: P | AI15: =IF($A15="","",COUNTIF($D15:$AH15,"P")) | AJ15: =IF($A15="","",COUNTIF($D15:$AH15,"AA")+COUNTIF($D15:$AH15,"SA")+COUNTIF($D15:$AH15,"EA")+COUNTIF($D15:$AH15,"OR")+COUNTIF($D15:$AH15,"WO")+COUNTIF($D15:$AH15,"H")) | AK15: =IF($A15="","",COUNTIF($D15:$AH15,"UA")) | AL15: =IF($A15="","",COUNTIF($D15:$AH15,"SA")) | AM15: =IF($A15="","",COUNTIF($D15:$AH15,"EA")) | AN15: =IF($A15="","",COUNTIF($D15:$AH15,"OR")) | AO15: =IF($A15="","",COUNTIF($D15:$AH15,"WO")) | AP15: =IF($A15="","",COUNTIF($D15:$AH15,"H")) | AS15: =IF(OR($A15="",$I$2=0),"",AI15/$I$2) | AT15: =IF(OR($A15="",$I$2=0),"",(AI15+AJ15)/$I$2) | AU15: =IF($A15="","",IF(OR($AK15>=2,AND($AK15>0,$AQ15=""),AND($AK15>0,$AR15="")),"CRITICAL",IF(OR($AK15=1,AND(($AJ15)>0,$AQ15=""),AND(($AJ15)>0,$AR15=""),$AT15<0.95),"REVIEW","OK")))
A16: =IF('Employee Master'!A16="","",'Employee Master'!A16) | B16: =IF($A16="","",'Employee Master'!B16) | C16: =IF($A16="","",'Employee Master'!C16) | D16: P | E16: P | F16: P | G16: P | H16: P | I16: P | J16: P | K16: P | L16: P | M16: UA | N16: P | O16: P | P16: P | Q16: P | R16: P | S16: P | T16: P | U16: P | V16: P | W16: P | X16: P | Y16: P | Z16: P | AA16: P | AB16: P | AC16: P | AD16: P | AE16: P | AI16: =IF($A16="","",COUNTIF($D16:$AH16,"P")) | AJ16: =IF($A16="","",COUNTIF($D16:$AH16,"AA")+COUNTIF($D16:$AH16,"SA")+COUNTIF($D16:$AH16,"EA")+COUNTIF($D16:$AH16,"OR")+COUNTIF($D16:$AH16,"WO")+COUNTIF($D16:$AH16,"H")) | AK16: =IF($A16="","",COUNTIF($D16:$AH16,"UA")) | AL16: =IF($A16="","",COUNTIF($D16:$AH16,"SA")) | AM16: =IF($A16="","",COUNTIF($D16:$AH16,"EA")) | AN16: =IF($A16="","",COUNTIF($D16:$AH16,"OR")) | AO16: =IF($A16="","",COUNTIF($D16:$AH16,"WO")) | AP16: =IF($A16="","",COUNTIF($D16:$AH16,"H")) | AS16: =IF(OR($A16="",$I$2=0),"",AI16/$I$2) | AT16: =IF(OR($A16="",$I$2=0),"",(AI16+AJ16)/$I$2) | AU16: =IF($A16="","",IF(OR($AK16>=2,AND($AK16>0,$AQ16=""),AND($AK16>0,$AR16="")),"CRITICAL",IF(OR($AK16=1,AND(($AJ16)>0,$AQ16=""),AND(($AJ16)>0,$AR16=""),$AT16<0.95),"REVIEW","OK")))
A17: =IF('Employee Master'!A17="","",'Employee Master'!A17) | B17: =IF($A17="","",'Employee Master'!B17) | C17: =IF($A17="","",'Employee Master'!C17) | D17: P | E17: P | F17: P | G17: P | H17: P | I17: P | J17: P | K17: P | L17: P | M17: P | N17: P | O17: P | P17: P | Q17: P | R17: P | S17: P | T17: P | U17: P | V17: P | W17: P | X17: P | Y17: P | Z17: P | AA17: P | AB17: P | AC17: P | AD17: P | AE17: P | AI17: =IF($A17="","",COUNTIF($D17:$AH17,"P")) | AJ17: =IF($A17="","",COUNTIF($D17:$AH17,"AA")+COUNTIF($D17:$AH17,"SA")+COUNTIF($D17:$AH17,"EA")+COUNTIF($D17:$AH17,"OR")+COUNTIF($D17:$AH17,"WO")+COUNTIF($D17:$AH17,"H")) | AK17: =IF($A17="","",COUNTIF($D17:$AH17,"UA")) | AL17: =IF($A17="","",COUNTIF($D17:$AH17,"SA")) | AM17: =IF($A17="","",COUNTIF($D17:$AH17,"EA")) | AN17: =IF($A17="","",COUNTIF($D17:$AH17,"OR")) | AO17: =IF($A17="","",COUNTIF($D17:$AH17,"WO")) | AP17: =IF($A17="","",COUNTIF($D17:$AH17,"H")) | AS17: =IF(OR($A17="",$I$2=0),"",AI17/$I$2) | AT17: =IF(OR($A17="",$I$2=0),"",(AI17+AJ17)/$I$2) | AU17: =IF($A17="","",IF(OR($AK17>=2,AND($AK17>0,$AQ17=""),AND($AK17>0,$AR17="")),"CRITICAL",IF(OR($AK17=1,AND(($AJ17)>0,$AQ17=""),AND(($AJ17)>0,$AR17=""),$AT17<0.95),"REVIEW","OK")))
A18: =IF('Employee Master'!A18="","",'Employee Master'!A18) | B18: =IF($A18="","",'Employee Master'!B18) | C18: =IF($A18="","",'Employee Master'!C18) | D18: P | E18: P | F18: P | G18: P | H18: P | I18: P | J18: P | K18: P | L18: P | M18: P | N18: P | O18: P | P18: P | Q18: P | R18: P | S18: P | T18: P | U18: P | V18: P | W18: P | X18: P | Y18: P | Z18: P | AA18: P | AB18: P | AC18: P | AD18: P | AE18: P | AI18: =IF($A18="","",COUNTIF($D18:$AH18,"P")) | AJ18: =IF($A18="","",COUNTIF($D18:$AH18,"AA")+COUNTIF($D18:$AH18,"SA")+COUNTIF($D18:$AH18,"EA")+COUNTIF($D18:$AH18,"OR")+COUNTIF($D18:$AH18,"WO")+COUNTIF($D18:$AH18,"H")) | AK18: =IF($A18="","",COUNTIF($D18:$AH18,"UA")) | AL18: =IF($A18="","",COUNTIF($D18:$AH18,"SA")) | AM18: =IF($A18="","",COUNTIF($D18:$AH18,"EA")) | AN18: =IF($A18="","",COUNTIF($D18:$AH18,"OR")) | AO18: =IF($A18="","",COUNTIF($D18:$AH18,"WO")) | AP18: =IF($A18="","",COUNTIF($D18:$AH18,"H")) | AS18: =IF(OR($A18="",$I$2=0),"",AI18/$I$2) | AT18: =IF(OR($A18="",$I$2=0),"",(AI18+AJ18)/$I$2) | AU18: =IF($A18="","",IF(OR($AK18>=2,AND($AK18>0,$AQ18=""),AND($AK18>0,$AR18="")),"CRITICAL",IF(OR($AK18=1,AND(($AJ18)>0,$AQ18=""),AND(($AJ18)>0,$AR18=""),$AT18<0.95),"REVIEW","OK")))
A19: =IF('Employee Master'!A19="","",'Employee Master'!A19) | B19: =IF($A19="","",'Employee Master'!B19) | C19: =IF($A19="","",'Employee Master'!C19) | D19: P | E19: P | F19: P | G19: P | H19: P | I19: P | J19: P | K19: P | L19: P | M19: P | N19: P | O19: P | P19: UA | Q19: P | R19: P | S19: P | T19: P | U19: P | V19: P | W19: P | X19: P | Y19: P | Z19: P | AA19: P | AB19: P | AC19: P | AD19: P | AE19: P | AI19: =IF($A19="","",COUNTIF($D19:$AH19,"P")) | AJ19: =IF($A19="","",COUNTIF($D19:$AH19,"AA")+COUNTIF($D19:$AH19,"SA")+COUNTIF($D19:$AH19,"EA")+COUNTIF($D19:$AH19,"OR")+COUNTIF($D19:$AH19,"WO")+COUNTIF($D19:$AH19,"H")) | AK19: =IF($A19="","",COUNTIF($D19:$AH19,"UA")) | AL19: =IF($A19="","",COUNTIF($D19:$AH19,"SA")) | AM19: =IF($A19="","",COUNTIF($D19:$AH19,"EA")) | AN19: =IF($A19="","",COUNTIF($D19:$AH19,"OR")) | AO19: =IF($A19="","",COUNTIF($D19:$AH19,"WO")) | AP19: =IF($A19="","",COUNTIF($D19:$AH19,"H")) | AS19: =IF(OR($A19="",$I$2=0),"",AI19/$I$2) | AT19: =IF(OR($A19="",$I$2=0),"",(AI19+AJ19)/$I$2) | AU19: =IF($A19="","",IF(OR($AK19>=2,AND($AK19>0,$AQ19=""),AND($AK19>0,$AR19="")),"CRITICAL",IF(OR($AK19=1,AND(($AJ19)>0,$AQ19=""),AND(($AJ19)>0,$AR19=""),$AT19<0.95),"REVIEW","OK")))
A20: =IF('Employee Master'!A20="","",'Employee Master'!A20) | B20: =IF($A20="","",'Employee Master'!B20) | C20: =IF($A20="","",'Employee Master'!C20) | D20: P | E20: P | F20: P | G20: P | H20: P | I20: P | J20: P | K20: P | L20: P | M20: P | N20: P | O20: P | P20: P | Q20: P | R20: P | S20: P | T20: P | U20: P | V20: P | W20: P | X20: P | Y20: P | Z20: P | AA20: P | AB20: P | AC20: P | AD20: P | AE20: P | AI20: =IF($A20="","",COUNTIF($D20:$AH20,"P")) | AJ20: =IF($A20="","",COUNTIF($D20:$AH20,"AA")+COUNTIF($D20:$AH20,"SA")+COUNTIF($D20:$AH20,"EA")+COUNTIF($D20:$AH20,"OR")+COUNTIF($D20:$AH20,"WO")+COUNTIF($D20:$AH20,"H")) | AK20: =IF($A20="","",COUNTIF($D20:$AH20,"UA")) | AL20: =IF($A20="","",COUNTIF($D20:$AH20,"SA")) | AM20: =IF($A20="","",COUNTIF($D20:$AH20,"EA")) | AN20: =IF($A20="","",COUNTIF($D20:$AH20,"OR")) | AO20: =IF($A20="","",COUNTIF($D20:$AH20,"WO")) | AP20: =IF($A20="","",COUNTIF($D20:$AH20,"H")) | AS20: =IF(OR($A20="",$I$2=0),"",AI20/$I$2) | AT20: =IF(OR($A20="",$I$2=0),"",(AI20+AJ20)/$I$2) | AU20: =IF($A20="","",IF(OR($AK20>=2,AND($AK20>0,$AQ20=""),AND($AK20>0,$AR20="")),"CRITICAL",IF(OR($AK20=1,AND(($AJ20)>0,$AQ20=""),AND(($AJ20)>0,$AR20=""),$AT20<0.95),"REVIEW","OK")))
A21: =IF('Employee Master'!A21="","",'Employee Master'!A21) | B21: =IF($A21="","",'Employee Master'!B21) | C21: =IF($A21="","",'Employee Master'!C21) | D21: UA | E21: UA | F21: UA | G21: UA | H21: UA | I21: UA | J21: UA | K21: UA | L21: UA | M21: UA | N21: UA | O21: UA | P21: UA | Q21: UA | R21: UA | S21: UA | T21: UA | U21: UA | V21: UA | W21: UA | X21: UA | Y21: UA | Z21: UA | AA21: P | AB21: P | AC21: P | AD21: P | AE21: P | AI21: =IF($A21="","",COUNTIF($D21:$AH21,"P")) | AJ21: =IF($A21="","",COUNTIF($D21:$AH21,"AA")+COUNTIF($D21:$AH21,"SA")+COUNTIF($D21:$AH21,"EA")+COUNTIF($D21:$AH21,"OR")+COUNTIF($D21:$AH21,"WO")+COUNTIF($D21:$AH21,"H")) | AK21: =IF($A21="","",COUNTIF($D21:$AH21,"UA")) | AL21: =IF($A21="","",COUNTIF($D21:$AH21,"SA")) | AM21: =IF($A21="","",COUNTIF($D21:$AH21,"EA")) | AN21: =IF($A21="","",COUNTIF($D21:$AH21,"OR")) | AO21: =IF($A21="","",COUNTIF($D21:$AH21,"WO")) | AP21: =IF($A21="","",COUNTIF($D21:$AH21,"H")) | AS21: =IF(OR($A21="",$I$2=0),"",AI21/$I$2) | AT21: =IF(OR($A21="",$I$2=0),"",(AI21+AJ21)/$I$2) | AU21: =IF($A21="","",IF(OR($AK21>=2,AND($AK21>0,$AQ21=""),AND($AK21>0,$AR21="")),"CRITICAL",IF(OR($AK21=1,AND(($AJ21)>0,$AQ21=""),AND(($AJ21)>0,$AR21=""),$AT21<0.95),"REVIEW","OK")))
A22: =IF('Employee Master'!A22="","",'Employee Master'!A22) | B22: =IF($A22="","",'Employee Master'!B22) | C22: =IF($A22="","",'Employee Master'!C22) | D22: P | E22: P | F22: P | G22: P | H22: P | I22: P | J22: P | K22: P | L22: P | M22: P | N22: P | O22: P | P22: P | Q22: P | R22: P | S22: P | T22: P | U22: P | V22: P | W22: P | X22: P | Y22: P | Z22: P | AA22: P | AB22: P | AC22: P | AD22: P | AE22: P | AI22: =IF($A22="","",COUNTIF($D22:$AH22,"P")) | AJ22: =IF($A22="","",COUNTIF($D22:$AH22,"AA")+COUNTIF($D22:$AH22,"SA")+COUNTIF($D22:$AH22,"EA")+COUNTIF($D22:$AH22,"OR")+COUNTIF($D22:$AH22,"WO")+COUNTIF($D22:$AH22,"H")) | AK22: =IF($A22="","",COUNTIF($D22:$AH22,"UA")) | AL22: =IF($A22="","",COUNTIF($D22:$AH22,"SA")) | AM22: =IF($A22="","",COUNTIF($D22:$AH22,"EA")) | AN22: =IF($A22="","",COUNTIF($D22:$AH22,"OR")) | AO22: =IF($A22="","",COUNTIF($D22:$AH22,"WO")) | AP22: =IF($A22="","",COUNTIF($D22:$AH22,"H")) | AS22: =IF(OR($A22="",$I$2=0),"",AI22/$I$2) | AT22: =IF(OR($A22="",$I$2=0),"",(AI22+AJ22)/$I$2) | AU22: =IF($A22="","",IF(OR($AK22>=2,AND($AK22>0,$AQ22=""),AND($AK22>0,$AR22="")),"CRITICAL",IF(OR($AK22=1,AND(($AJ22)>0,$AQ22=""),AND(($AJ22)>0,$AR22=""),$AT22<0.95),"REVIEW","OK")))
... A71: =IF('Employee Master'!A71="","",'Employee Master'!A71) | B71: =IF($A71="","",'Employee Master'!B71) | C71: =IF($A71="","",'Employee Master'!C71) | D71: P | E71: P | F71: P | G71: P | H71: P | I71: P | J71: P | K71: P | L71: P | M71: P | N71: P | O71: P | P71: P | Q71: P | R71: P | S71: P | T71: P | U71: P | V71: P | W71: P | X71: P | Y71: P | Z71: P | AA71: P | AB71: P | AC71: P | AD71: P | AE71: P | AI71: =IF($A71="","",COUNTIF($D71:$AH71,"P")) | AJ71: =IF($A71="","",COUNTIF($D71:$AH71,"AA")+COUNTIF($D71:$AH71,"SA")+COUNTIF($D71:$AH71,"EA")+COUNTIF($D71:$AH71,"OR")+COUNTIF($D71:$AH71,"WO")+COUNTIF($D71:$AH71,"H")) | AK71: =IF($A71="","",COUNTIF($D71:$AH71,"UA")) | AL71: =IF($A71="","",COUNTIF($D71:$AH71,"SA")) | AM71: =IF($A71="","",COUNTIF($D71:$AH71,"EA")) | AN71: =IF($A71="","",COUNTIF($D71:$AH71,"OR")) | AO71: =IF($A71="","",COUNTIF($D71:$AH71,"WO")) | AP71: =IF($A71="","",COUNTIF($D71:$AH71,"H")) | AS71: =IF(OR($A71="",$I$2=0),"",AI71/$I$2) | AT71: =IF(OR($A71="",$I$2=0),"",(AI71+AJ71)/$I$2) | AU71: =IF($A71="","",IF(OR($AK71>=2,AND($AK71>0,$AQ71=""),AND($AK71>0,$AR71="")),"CRITICAL",IF(OR($AK71=1,AND(($AJ71)>0,$AQ71=""),AND(($AJ71)>0,$AR71=""),$AT71<0.95),"REVIEW","OK")))
